<?xml version="1.0"?>
<robot name="robotic_arm">
  <link name="base_link">
    <visual>
      <geometry>
        <mesh filename="package://robotic_arm/mesh/1.dae" scale="10 10 10"/>

        <origin xyz="0 0 0" rpy="0 0 0" />
      </geometry>
    </visual>
  </link>

  <link name="link2">
    <visual>
      <geometry>
        <mesh filename="package://robotic_arm/mesh/2.dae" scale="10 10 10"/>

        <origin xyz="0 0 0" rpy="0 0 0" />
      </geometry>
    </visual>
  </link>

  <link name="link3">
    <visual>
      <geometry>
        <mesh filename="package://robotic_arm/mesh/3.dae" scale="10 10 10"/>

        <origin xyz="0 0 0" rpy="0 0 0"/>
      </geometry>
    </visual>
  </link>

  <link name="link4">
    <visual>
      <geometry>
        <mesh filename="package://robotic_arm/mesh/4_.dae" scale="10 10 10"/>

        <origin xyz="0 0 0" rpy="0 0 0"/>
      </geometry>
    </visual>
  </link>

  <link name="link5">
    <visual>
      <geometry>
        <box size="0.12 0.02 0.01"/>
        <origin xyz="0 0 0" rpy="0 0 0"/>
      </geometry>
    </visual>
  </link>

  <link name="link6">
    <visual>
        <geometry>
            <box size="0.01 0.016 0.035"/>
            <origin xyz="0 0 0" rpz="0 0 0"/>
        </geometry>
    </visual>
  </link>


<link name="link7">
    <visual>
        <geometry>
            <box size="0.01 0.016 0.035"/>
            <origin xyz="0 0 0" rpz="0 0 0"/>
        </geometry>
    </visual>
  </link>

  <joint name="base_link2" type="revolute">
    <parent link="base_link"/>
    <child link="link2"/>
    <origin xyz="0 0 0.1" rpy="0 0 0"/>
    <axis xyz="0 0 1"/>
    <limit effort="300" velocity="2.0" lower="-3.14" upper="3.14"/>
  </joint>

  <joint name="link2_link3" type="revolute">
    <parent link="link2"/>
    <child link="link3"/>
    <origin xyz="0 0 0.1" rpy="0 0 0"/>
    <axis xyz="1 0 0" />
    <limit effort="300" velocity="2.0" lower="-1.57" upper="1.57"/>
  </joint>

  <joint name="link3_link4" type="revolute">
    <parent link="link3"/>
    <child link="link4"/>
    <origin xyz="0 0 0.45" rpy="0 0 0"/>
    <axis xyz="1 0 0" />
    <limit effort="300" velocity="2.0" lower="-1.57" upper="1.57"/>
  </joint>

  <!--gripper-->

  <joint name="link4_link5" type="fixed">
    <parent link="link4"/>
    <child link="link5"/>
    <origin xyz="0 0 0.5" rpy="0 0 0"/> 
    <axis xyz="0 1 0"/>
  </joint>

  <joint name="link5_link6" type="prismatic">
    <parent link="link5"/>
    <child link="link6"/>
    <origin xyz="-0.008 0 0.02 " rpz="0 0 0"/>
    <axis xyz="-1 0 0"/>
    <limit lower="0.0" upper="0.05" effort="10.0" velocity="0.5"/>
  </joint>

  <joint name="link5_link7" type="prismatic">
    <parent link="link5"/>
    <child link="link7"/>
    <origin xyz="0.008 0 0.02 " rpz="0 0 0"/>
    <axis xyz="1 0 0"/>
    <limit lower="0.0" upper="0.05" effort="10.0" velocity="0.5"/>
    <mimic joint="link5_link6" multiplier="1.0" offset="0.0"/>
  </joint>
</robot>