<?xml version="1.0"?>
<robot name="robotic_arm">
  <link name="base_link">
    <visual>
      <geometry>
        <mesh filename="package://robotic_arm/mesh/1.dae" scale="10 10 10"/>

        <origin xyz="0 0 0" rpy="0 0 0" />
      </geometry>
    </visual>
  </link>

  <link name="link2">
    <visual>
      <geometry>
        <mesh filename="package://robotic_arm/mesh/2.dae" scale="10 10 10"/>

        <origin xyz="0 0 0" rpy="0 0 0" />
      </geometry>
    </visual>
  </link>

  <link name="link3">
    <visual>
      <geometry>
        <mesh filename="package://robotic_arm/mesh/3.dae" scale="10 10 10"/>

        <origin xyz="0 0 0" rpy="0 0 0"/>
      </geometry>
    </visual>
  </link>

  <link name="link4">
    <visual>
      <geometry>
        <mesh filename="package://robotic_arm/mesh/4.dae" scale="10 10 10"/>

        <origin xyz="0 0 0" rpy="0 0 0"/>
      </geometry>
    </visual>
  </link>

  <joint name="base_link2" type="revolute">
    <parent link="base_link"/>
    <child link="link2"/>
    <origin xyz="0 0 0.1" rpy="0 0 0"/>
    <axis xyz="0 0 1"/>
    <limit effort="300" velocity="2.0" lower="-3.14" upper="3.14"/>
  </joint>

  <joint name="link2_link3" type="revolute">
    <parent link="link2"/>
    <child link="link3"/>
    <origin xyz="0 0 0.1" rpy="0 0 0"/>
    <axis xyz="1 0 0" />
    <limit effort="300" velocity="2.0" lower="-1.57" upper="1.57"/>
  </joint>

  <joint name="link3_link4" type="revolute">
    <parent link="link3"/>
    <child link="link4"/>
    <origin xyz="0 0 0.45" rpy="0 0 0"/>
    <axis xyz="1 0 0" />
    <limit effort="300" velocity="2.0" lower="-1.57" upper="1.57"/>
  </joint>
</robot>